<?php

declare(strict_types=1);

namespace Testo\Assert\Interceptor;

use Testo\Assert\State;
use Testo\Assert\State\AssertException;
use Testo\Assert\State\Record;
use Testo\Assert\State\Success;
use Testo\Assert\StaticState;
use Testo\Interceptor\TestRunInterceptor;
use Testo\Test\Dto\Status;
use Testo\Test\Dto\TestInfo;
use Testo\Test\Dto\TestResult;

/**
 * Interceptor to handle expected exceptions.
 *
 * @note Must be placed right before the test execution.
 */
final class ExpectExceptionInterceptor implements TestRunInterceptor
{
    /**
     * @throws AssertException When the expected exception is not thrown.
     */
    #[\Override]
    public function runTest(TestInfo $info, callable $next): TestResult
    {
        /** @var TestResult $result */
        $result = $next($info);
        $context = StaticState::current();
        $expectation = $context?->expectException;

        # No state or expectation defined
        if ($expectation === null) {
            # Test failed due to an assertion failure
            if ($result->status->isFailure() && $result->failure instanceof AssertException) {
                $result = $result->with(status: Status::Failed);
            }

            return $result;
        }

        # An expectation was defined
        # Check if the expectation was met
        $record = self::isPassed($expectation, $result->failure);
        $context->history[] = $record;
        $context->expectException = null;

        # Special case: Assert::fail() was called (expectation is AssertException instance)
        # but the exception was caught, so test ended successfully without throwing
        # This is suspicious behavior â†’ mark as Risky
        if ($result->failure === null
            && $expectation->classOrObject instanceof AssertException
            && !$record->isSuccess()) {
            return $result->with(status: Status::Risky)->withFailure($record);
        }

        return $record->isSuccess()
            ? $result->with(status: Status::Passed)
            : $result->with(status: Status::Failed)->withFailure($record);
    }

    private static function isPassed(State\ExpectedException $expected, ?\Throwable $actual): Record|AssertException
    {
        $class = \is_string($expected->classOrObject) ? $expected->classOrObject : $expected->classOrObject::class;
        if (\is_object($expected->classOrObject) ? $actual === $expected->classOrObject : $actual instanceof $class) {
            return new Success(
                assertion: $class === $actual::class
                    ? 'Throw exception: `' . $class . '`.'
                    : 'Throw exception: `' . $class . '` (got `' . $actual::class . '`).',
            );
        }

        return AssertException::exceptionClass($class, $actual);
    }
}
